Node: fmriprep_25_1_wf.sub_16_wf.bold_task_analogy_run_07_wf.bold_fit_wf.hmc_boldref_wf.validation_and_dummies_wf.get_dummy
Working directory: /tmp/work/fmriprep_25_1_wf/sub_16_wf/bold_task_analogy_run_07_wf/bold_fit_wf/hmc_boldref_wf/validation_and_dummies_wf/get_dummy

Node inputs:

in_file = /data/sub-16/func/sub-16_task-analogy_run-07_bold.nii.gz
n_volumes = 40
nonnegative = True
zero_dummy_masked = 20

Traceback (most recent call last):
  File "/opt/conda/envs/fmriprep/lib/python3.12/site-packages/nipype/pipeline/plugins/multiproc.py", line 67, in run_node
    result["result"] = node.run(updatehash=updatehash)
                       ^^^^^^^^^^^^^^^^^^^^^^^^^^^^^^^
  File "/opt/conda/envs/fmriprep/lib/python3.12/site-packages/nipype/pipeline/engine/nodes.py", line 525, in run
    result = self._run_interface(execute=True)
             ^^^^^^^^^^^^^^^^^^^^^^^^^^^^^^^^^
  File "/opt/conda/envs/fmriprep/lib/python3.12/site-packages/nipype/pipeline/engine/nodes.py", line 643, in _run_interface
    return self._run_command(execute)
           ^^^^^^^^^^^^^^^^^^^^^^^^^^
  File "/opt/conda/envs/fmriprep/lib/python3.12/site-packages/nipype/pipeline/engine/nodes.py", line 769, in _run_command
    raise NodeExecutionError(msg)
nipype.pipeline.engine.nodes.NodeExecutionError: Exception raised while executing Node get_dummy.

Traceback:
	Traceback (most recent call last):
	  File "/opt/conda/envs/fmriprep/lib/python3.12/site-packages/nipype/interfaces/base/core.py", line 401, in run
	    runtime = self._run_interface(runtime)
	              ^^^^^^^^^^^^^^^^^^^^^^^^^^^^
	  File "/opt/conda/envs/fmriprep/lib/python3.12/site-packages/niworkflows/interfaces/bold.py", line 86, in _run_interface
	    data = img.get_fdata(dtype='float32')[..., : self.inputs.n_volumes]
	           ^^^^^^^^^^^^^^^^^^^^^^^^^^^^^^
	  File "/opt/conda/envs/fmriprep/lib/python3.12/site-packages/nibabel/dataobj_images.py", line 374, in get_fdata
	    data = np.asanyarray(self._dataobj, dtype=dtype)
	           ^^^^^^^^^^^^^^^^^^^^^^^^^^^^^^^^^^^^^^^^^
	  File "/opt/conda/envs/fmriprep/lib/python3.12/site-packages/nibabel/arrayproxy.py", line 454, in __array__
	    arr = self._get_scaled(dtype=dtype, slicer=())
	          ^^^^^^^^^^^^^^^^^^^^^^^^^^^^^^^^^^^^^^^^
	  File "/opt/conda/envs/fmriprep/lib/python3.12/site-packages/nibabel/arrayproxy.py", line 421, in _get_scaled
	    scaled = apply_read_scaling(self._get_unscaled(slicer=slicer), scl_slope, scl_inter)
	                                ^^^^^^^^^^^^^^^^^^^^^^^^^^^^^^^^^
	  File "/opt/conda/envs/fmriprep/lib/python3.12/site-packages/nibabel/arrayproxy.py", line 391, in _get_unscaled
	    return array_from_file(
	           ^^^^^^^^^^^^^^^^
	  File "/opt/conda/envs/fmriprep/lib/python3.12/site-packages/nibabel/volumeutils.py", line 474, in array_from_file
	    raise OSError(
	OSError: Expected 376396800 bytes, got 144232646 bytes from object
	 - could the file be damaged?

